Time slot   0
ld_routine
Time slot   1
	Loaded a process at input/proc/p1s, PID: 1 PRIO: 15
Time slot   2
	CPU 3: Dispatched process  1
Time slot   3
Time slot   4
	CPU 3: Put process  1 to run queue
	CPU 3: Dispatched process  1
Time slot   5
	Loaded a process at input/proc/m0s, PID: 2 PRIO: 120
Time slot   6
	CPU 3: Put process  1 to run queue
	CPU 3: Dispatched process  1
	CPU 2: Dispatched process  2
liballoc:178
print_pgtbl:
 PDG=bbd20d000 P4g=bbd212000 PUD=bbd213000 PMD=bbac06000
Time slot   7
liballoc:178
print_pgtbl:
 PDG=bbd20d000 P4g=bbd212000 PUD=bbd213000 PMD=bbac06000
	Loaded a process at input/proc/p0s, PID: 3 PRIO: 130
Time slot   8
	CPU 3: Put process  1 to run queue
	CPU 3: Dispatched process  1
	CPU 2: Put process  2 to run queue
	CPU 2: Dispatched process  2
libfree:218
print_pgtbl:
 PDG=bbd20d000 P4g=bbd212000 PUD=bbd213000 PMD=bbac06000
	CPU 1: Dispatched process  3
Time slot   9
	Loaded a process at input/proc/s0, PID: 4 PRIO: 38
liballoc:178
print_pgtbl:
 PDG=bbd20d000 P4g=bbd212000 PUD=bbd213000 PMD=bbac06000
liballoc:178
print_pgtbl:
 PDG=bbd20e000 P4g=bbd218000 PUD=bbd219000 PMD=bbac08000
Time slot  10
	CPU 1: Put process  3 to run queue
	CPU 1: Dispatched process  4
	CPU 0: Dispatched process  3
liballoc:178
print_pgtbl:
 PDG=bbd20e000 P4g=bbd218000 PUD=bbd219000 PMD=bbac08000
	CPU 3: Put process  1 to run queue
	CPU 3: Dispatched process  1
	CPU 2: Put process  2 to run queue
	CPU 2: Dispatched process  2
libwrite:502
print_pgtbl:
 PDG=bbd20d000 P4g=bbd212000 PUD=bbd213000 PMD=bbac06000
Time slot  11
	Loaded a process at input/proc/s3, PID: 5 PRIO: 39
libwrite:502
print_pgtbl:
 PDG=bbd20d000 P4g=bbd212000 PUD=bbd213000 PMD=bbac06000
libfree:218
print_pgtbl:
 PDG=bbd20e000 P4g=bbd218000 PUD=bbd219000 PMD=bbac08000
Time slot  12
	CPU 3: Put process  1 to run queue
	CPU 3: Dispatched process  1
	CPU 1: Put process  4 to run queue
	CPU 1: Dispatched process  4
	CPU 2: Processed  2 has finished
	CPU 2: Dispatched process  5
	CPU 0: Put process  3 to run queue
	CPU 0: Dispatched process  3
liballoc:178
print_pgtbl:
 PDG=bbd20e000 P4g=bbd218000 PUD=bbd219000 PMD=bbac08000
Time slot  13
libwrite:502
print_pgtbl:
 PDG=bbd20e000 P4g=bbd218000 PUD=bbd219000 PMD=bbac08000
Time slot  14
	Loaded a process at input/proc/m1s, PID: 6 PRIO: 15
	CPU 1: Put process  4 to run queue
	CPU 1: Dispatched process  6
liballoc:178
print_pgtbl:
	CPU 3: Put process  1 to run queue
	CPU 3: Dispatched process  1
 PDG=bbd21d000 P4g=bbd222000 PUD=bbd223000 PMD=bbac0e000
	CPU 2: Put process  5 to run queue
	CPU 2: Dispatched process  4
	CPU 0: Put process  3 to run queue
	CPU 0: Dispatched process  5
Time slot  15
liballoc:178
print_pgtbl:
 PDG=bbd21d000 P4g=bbd222000 PUD=bbd223000 PMD=bbac0e000
Time slot  16
	CPU 3: Put process  1 to run queue
	CPU 3: Dispatched process  1
	CPU 2: Put process  4 to run queue
	CPU 2: Dispatched process  4
	CPU 1: Put process  6 to run queue
	CPU 1: Dispatched process  6
libfree:218
print_pgtbl:
 PDG=bbd21d000 P4g=bbd222000 PUD=bbd223000 PMD=bbac0e000
	Loaded a process at input/proc/s2, PID: 7 PRIO: 120
	CPU 0: Put process  5 to run queue
	CPU 0: Dispatched process  5
Time slot  17
liballoc:178
print_pgtbl:
 PDG=bbd21d000 P4g=bbd222000 PUD=bbd223000 PMD=bbac0e000
	Loaded a process at input/proc/s1, PID: 8 PRIO: 0
Time slot  18
	CPU 3: Put process  1 to run queue
	CPU 3: Dispatched process  8
	CPU 2: Put process  4 to run queue
	CPU 2: Dispatched process  1
	CPU 0: Put process  5 to run queue
	CPU 0: Dispatched process  4
	CPU 1: Put process  6 to run queue
	CPU 1: Dispatched process  6
libfree:218
print_pgtbl:
 PDG=bbd21d000 P4g=bbd222000 PUD=bbd223000 PMD=bbac0e000
Time slot  19
libfree:218
print_pgtbl:
 PDG=bbd21d000 P4g=bbd222000 PUD=bbd223000 PMD=bbac0e000
Time slot  20
	CPU 3: Put process  8 to run queue
	CPU 3: Dispatched process  8
	CPU 2: Put process  1 to run queue
	CPU 1: Processed  6 has finished
	CPU 2: Dispatched process  1
	CPU 0: Put process  4 to run queue
	CPU 0: Dispatched process  4
	CPU 1: Dispatched process  5
Time slot  21
	CPU 2: Processed  1 has finished
	CPU 2: Dispatched process  7
Time slot  22
	CPU 3: Put process  8 to run queue
	CPU 3: Dispatched process  8
	CPU 1: Put process  5 to run queue
	CPU 1: Dispatched process  5
	CPU 0: Put process  4 to run queue
	CPU 0: Dispatched process  4
Time slot  23
	CPU 2: Put process  7 to run queue
	CPU 2: Dispatched process  7
Time slot  24
	CPU 3: Put process  8 to run queue
	CPU 3: Dispatched process  8
	CPU 1: Put process  5 to run queue
	CPU 1: Dispatched process  5
	CPU 0: Put process  4 to run queue
	CPU 0: Dispatched process  4
Time slot  25
	CPU 2: Put process  7 to run queue
	CPU 2: Dispatched process  7
	CPU 0: Processed  4 has finished
	CPU 0: Dispatched process  3
libread:426
print_pgtbl:
 PDG=bbd20e000 P4g=bbd218000 PUD=bbd219000 PMD=bbac08000
Time slot  26
	CPU 3: Put process  8 to run queue
	CPU 3: Dispatched process  8
libwrite:502
print_pgtbl:
 PDG=bbd20e000 P4g=bbd218000 PUD=bbd219000 PMD=bbac08000
	CPU 1: Put process  5 to run queue
	CPU 1: Dispatched process  5
Time slot  27
	CPU 3: Processed  8 has finished
	CPU 2: Put process  7 to run queue
	CPU 2: Dispatched process  7
	CPU 3 stopped
	CPU 0: Put process  3 to run queue
	CPU 0: Dispatched process  3
libread:426
print_pgtbl:
 PDG=bbd20e000 P4g=bbd218000 PUD=bbd219000 PMD=bbac08000
Time slot  28
	CPU 1: Put process  5 to run queue
	CPU 1: Dispatched process  5
libwrite:502
print_pgtbl:
 PDG=bbd20e000 P4g=bbd218000 PUD=bbd219000 PMD=bbac08000
Time slot  29
	CPU 2: Put process  7 to run queue
	CPU 2: Dispatched process  7
	CPU 0: Put process  3 to run queue
	CPU 0: Dispatched process  3
libread:426
print_pgtbl:
 PDG=bbd20e000 P4g=bbd218000 PUD=bbd219000 PMD=bbac08000
Time slot  30
	CPU 1: Processed  5 has finished
	CPU 1 stopped
Time slot  31
	CPU 2: Put process  7 to run queue
	CPU 2: Dispatched process  7
	CPU 0: Put process  3 to run queue
	CPU 0: Dispatched process  3
libfree:218
print_pgtbl:
 PDG=bbd20e000 P4g=bbd218000 PUD=bbd219000 PMD=bbac08000
Time slot  32
Time slot  33
	CPU 2: Processed  7 has finished
	CPU 0: Processed  3 has finished
	CPU 2 stopped
	CPU 0 stopped
