Time slot   0
ld_routine
Time slot   1
	Loaded a process at input/proc/p0s, PID: 1 PRIO: 130
Time slot   2
	CPU 3: Dispatched process  1
	Loaded a process at input/proc/m0s, PID: 2 PRIO: 120
Time slot   3
liballoc:178
print_pgtbl:
 PDG=ba720d000 P4g=105566f80 PUD=ba7210000 PMD=ba6c05000
	CPU 2: Dispatched process  2
liballoc:178
print_pgtbl:
 PDG=ba720e000 P4g=ba7211000 PUD=ba7212000 PMD=ba6c07000
Time slot   4
	CPU 3: Put process  1 to run queue
liballoc:178
print_pgtbl:
 PDG=ba720e000 P4g=ba7211000 PUD=ba7212000 PMD=ba6c07000
	CPU 3: Dispatched process  1
liballoc:178
print_pgtbl:
 PDG=ba720d000 P4g=105566f80 PUD=ba7210000 PMD=ba6c05000
	Loaded a process at input/proc/s3, PID: 3 PRIO: 39
Time slot   5
libfree:218
print_pgtbl:
 PDG=ba720d000 P4g=105566f80 PUD=ba7210000 PMD=ba6c05000
	CPU 2: Put process  2 to run queue
	CPU 2: Dispatched process  2
libfree:218
print_pgtbl:
	CPU 1: Dispatched process  3
 PDG=ba720e000 P4g=ba7211000 PUD=ba7212000 PMD=ba6c07000
	Loaded a process at input/proc/s0, PID: 4 PRIO: 38
Time slot   6
	CPU 3: Put process  1 to run queue
liballoc:178
print_pgtbl:
 PDG=ba720e000 P4g=ba7211000 PUD=ba7212000 PMD=ba6c07000
	CPU 0: Dispatched process  1
liballoc:178
print_pgtbl:
 PDG=ba720d000 P4g=105566f80 PUD=ba7210000 PMD=ba6c05000
	CPU 3: Dispatched process  4
Time slot   7
	CPU 2: Put process  2 to run queue
	CPU 1: Put process  3 to run queue
	CPU 1: Dispatched process  3
	CPU 2: Dispatched process  2
libwrite:502
print_pgtbl:
 PDG=ba720e000 P4g=ba7211000 PUD=ba7212000 PMD=ba6c07000
libwrite:502
print_pgtbl:
 PDG=ba720d000 P4g=105566f80 PUD=ba7210000 PMD=ba6c05000
Time slot   8
	CPU 3: Put process  4 to run queue
	CPU 3: Dispatched process  4
libwrite:502
print_pgtbl:
 PDG=ba720e000 P4g=ba7211000 PUD=ba7212000 PMD=ba6c07000
	CPU 0: Put process  1 to run queue
	CPU 0: Dispatched process  1
libread:426
print_pgtbl:
 PDG=ba720d000 P4g=105566f80 PUD=ba7210000 PMD=ba6c05000
Time slot   9
	CPU 2: Processed  2 has finished
libwrite:502
print_pgtbl:
 PDG=ba720d000 P4g=105566f80 PUD=ba7210000 PMD=ba6c05000
	CPU 1: Put process  3 to run queue
	CPU 1: Dispatched process  3
	Loaded a process at input/proc/m1s, PID: 5 PRIO: 15
Time slot  10
	CPU 3: Put process  4 to run queue
	CPU 2: Dispatched process  5
liballoc:178
	CPU 3: Dispatched process  4
	CPU 0: Put process  1 to run queue
	CPU 0: Dispatched process  1
libread:426
print_pgtbl:
 PDG=ba720d000 P4g=105566f80 PUD=ba7210000 PMD=ba6c05000
print_pgtbl:
 PDG=ba721d000 P4g=ba721b000 PUD=ba7220000 PMD=ba6c0d000
Time slot  11
	Loaded a process at input/proc/p1s, PID: 6 PRIO: 15
libwrite:502
print_pgtbl:
 PDG=ba720d000 P4g=105566f80 PUD=ba7210000 PMD=ba6c05000
	CPU 1: Put process  3 to run queue
	CPU 1: Dispatched process  6
liballoc:178
print_pgtbl:
 PDG=ba721d000 P4g=ba721b000 PUD=ba7220000 PMD=ba6c0d000
Time slot  12
	CPU 3: Put process  4 to run queue
	CPU 2: Put process  5 to run queue
	CPU 2: Dispatched process  5
libfree:218
print_pgtbl:
	CPU 3: Dispatched process  4
	CPU 0: Put process  1 to run queue
	CPU 0: Dispatched process  3
 PDG=ba721d000 P4g=ba721b000 PUD=ba7220000 PMD=ba6c0d000
Time slot  13
liballoc:178
print_pgtbl:
 PDG=ba721d000 P4g=ba721b000 PUD=ba7220000 PMD=ba6c0d000
	CPU 1: Put process  6 to run queue
	CPU 1: Dispatched process  6
	Loaded a process at input/proc/s2, PID: 7 PRIO: 120
Time slot  14
	CPU 3: Put process  4 to run queue
	CPU 3: Dispatched process  4
	CPU 0: Put process  3 to run queue
	CPU 0: Dispatched process  3
	CPU 2: Put process  5 to run queue
	CPU 2: Dispatched process  5
libfree:218
print_pgtbl:
 PDG=ba721d000 P4g=ba721b000 PUD=ba7220000 PMD=ba6c0d000
Time slot  15
libfree:218
print_pgtbl:
 PDG=ba721d000 P4g=ba721b000 PUD=ba7220000 PMD=ba6c0d000
	CPU 1: Put process  6 to run queue
	CPU 1: Dispatched process  6
Time slot  16
	CPU 3: Put process  4 to run queue
	CPU 3: Dispatched process  4
	Loaded a process at input/proc/s1, PID: 8 PRIO: 0
	CPU 2: Processed  5 has finished
	CPU 2: Dispatched process  8
	CPU 0: Put process  3 to run queue
	CPU 0: Dispatched process  3
Time slot  17
	CPU 1: Put process  6 to run queue
	CPU 1: Dispatched process  6
Time slot  18
	CPU 3: Put process  4 to run queue
	CPU 0: Put process  3 to run queue
	CPU 0: Dispatched process  3
	CPU 2: Put process  8 to run queue
	CPU 2: Dispatched process  8
	CPU 3: Dispatched process  4
Time slot  19
	CPU 1: Put process  6 to run queue
	CPU 1: Dispatched process  6
Time slot  20
	CPU 3: Put process  4 to run queue
	CPU 0: Put process  3 to run queue
	CPU 0: Dispatched process  3
	CPU 2: Put process  8 to run queue
	CPU 2: Dispatched process  8
	CPU 3: Dispatched process  4
Time slot  21
	CPU 3: Processed  4 has finished
	CPU 1: Put process  6 to run queue
	CPU 1: Dispatched process  6
	CPU 3: Dispatched process  7
Time slot  22
	CPU 2: Put process  8 to run queue
	CPU 2: Dispatched process  8
	CPU 0: Processed  3 has finished
	CPU 0: Dispatched process  1
libread:426
print_pgtbl:
 PDG=ba720d000 P4g=105566f80 PUD=ba7210000 PMD=ba6c05000
Time slot  23
	CPU 3: Put process  7 to run queue
	CPU 3: Dispatched process  7
	CPU 1: Put process  6 to run queue
	CPU 1: Dispatched process  6
Time slot  24
	CPU 2: Put process  8 to run queue
	CPU 2: Dispatched process  8
	CPU 0: Put process  1 to run queue
	CPU 0: Dispatched process  1
libfree:218
print_pgtbl:
 PDG=ba720d000 P4g=105566f80 PUD=ba7210000 PMD=ba6c05000
Time slot  25
	CPU 3: Put process  7 to run queue
	CPU 3: Dispatched process  7
	CPU 1: Put process  6 to run queue
	CPU 1: Dispatched process  6
	CPU 2: Processed  8 has finished
	CPU 2 stopped
Time slot  26
	CPU 0: Processed  1 has finished
	CPU 0 stopped
Time slot  27
	CPU 3: Put process  7 to run queue
	CPU 3: Dispatched process  7
	CPU 1: Put process  6 to run queue
	CPU 1: Dispatched process  6
Time slot  28
Time slot  29
	CPU 3: Put process  7 to run queue
	CPU 3: Dispatched process  7
	CPU 1: Put process  6 to run queue
	CPU 1: Dispatched process  6
Time slot  30
	CPU 1: Processed  6 has finished
	CPU 1 stopped
Time slot  31
	CPU 3: Put process  7 to run queue
	CPU 3: Dispatched process  7
Time slot  32
Time slot  33
	CPU 3: Processed  7 has finished
	CPU 3 stopped
