Time slot   0
ld_routine
Time slot   1
	Loaded a process at input/proc/p0s, PID: 1 PRIO: 130
	CPU 2: Dispatched process  1
Time slot   2
liballoc:178
print_pgtbl:
 PDG=bdcc03000 P4g=bdd1e4000 PUD=bdcc04000 PMD=bdcc08000
Time slot   3
	Loaded a process at input/proc/m0s, PID: 2 PRIO: 120
	CPU 3: Dispatched process  2
liballoc:178
print_pgtbl:
 PDG=bdcc0e000 P4g=bdd1e5000 PUD=bdcc05000 PMD=bdcc09000
	CPU 2: Put process  1 to run queue
	CPU 2: Dispatched process  1
liballoc:178
print_pgtbl:
 PDG=bdcc03000 P4g=bdd1e4000 PUD=bdcc04000 PMD=bdcc08000
Time slot   4
liballoc:178
print_pgtbl:
 PDG=bdcc0e000 P4g=bdd1e5000 PUD=bdcc05000 PMD=bdcc09000
libfree:218
print_pgtbl:
 PDG=bdcc03000 P4g=bdd1e4000 PUD=bdcc04000 PMD=bdcc08000
Time slot   5
	Loaded a process at input/proc/s1, PID: 3 PRIO: 0
	CPU 0: Dispatched process  3
	CPU 2: Put process  1 to run queue
	CPU 2: Dispatched process  1
liballoc:178
print_pgtbl:
 PDG=bdcc03000 P4g=bdd1e4000 PUD=bdcc04000 PMD=bdcc08000
	CPU 3: Put process  2 to run queue
	CPU 3: Dispatched process  2
libfree:218
print_pgtbl:
 PDG=bdcc0e000 P4g=bdd1e5000 PUD=bdcc05000 PMD=bdcc09000
Time slot   6
	Loaded a process at input/proc/p1s, PID: 4 PRIO: 15
libwrite:502
print_pgtbl:
 PDG=bdcc03000 P4g=bdd1e4000 PUD=bdcc04000 PMD=bdcc08000
liballoc:178
print_pgtbl:
 PDG=bdcc0e000 P4g=bdd1e5000 PUD=bdcc05000 PMD=bdcc09000
	CPU 1: Dispatched process  4
Time slot   7
	CPU 3: Put process  2 to run queue
	CPU 0: Put process  3 to run queue
	CPU 0: Dispatched process  3
	CPU 3: Dispatched process  2
libwrite:502
print_pgtbl:
 PDG=bdcc0e000 P4g=bdd1e5000 PUD=bdcc05000 PMD=bdcc09000
	CPU 2: Put process  1 to run queue
	CPU 2: Dispatched process  1
libread:426
print_pgtbl:
 PDG=bdcc03000 P4g=bdd1e4000 PUD=bdcc04000 PMD=bdcc08000
Time slot   8
libwrite:502
print_pgtbl:
libwrite:502
print_pgtbl:
 PDG=bdcc0e000 P4g=bdd1e5000 PUD=bdcc05000 PMD=bdcc09000
 PDG=bdcc03000 P4g=bdd1e4000 PUD=bdcc04000 PMD=bdcc08000
	CPU 1: Put process  4 to run queue
	CPU 1: Dispatched process  4
Time slot   9
	Loaded a process at input/proc/s3, PID: 5 PRIO: 39
	CPU 3: Processed  2 has finished
	CPU 3: Dispatched process  5
	CPU 0: Put process  3 to run queue
	CPU 0: Dispatched process  3
	CPU 2: Put process  1 to run queue
	CPU 2: Dispatched process  1
libread:426
print_pgtbl:
 PDG=bdcc03000 P4g=bdd1e4000 PUD=bdcc04000 PMD=bdcc08000
Time slot  10
	Loaded a process at input/proc/s2, PID: 6 PRIO: 120
libwrite:502
print_pgtbl:
 PDG=bdcc03000 P4g=bdd1e4000 PUD=bdcc04000 PMD=bdcc08000
	CPU 1: Put process  4 to run queue
	CPU 1: Dispatched process  4
Time slot  11
	Loaded a process at input/proc/m1s, PID: 7 PRIO: 15
	CPU 3: Put process  5 to run queue
	CPU 3: Dispatched process  7
liballoc:178
print_pgtbl:
	CPU 0: Put process  3 to run queue
	CPU 0: Dispatched process  3
	CPU 2: Put process  1 to run queue
	CPU 2: Dispatched process  5
 PDG=bdcc21000 P4g=bdd1ea000 PUD=bdcc16000 PMD=bdcc1a000
Time slot  12
	Loaded a process at input/proc/s0, PID: 8 PRIO: 38
	CPU 1: Put process  4 to run queue
	CPU 1: Dispatched process  4
liballoc:178
print_pgtbl:
 PDG=bdcc21000 P4g=bdd1ea000 PUD=bdcc16000 PMD=bdcc1a000
Time slot  13
	CPU 3: Put process  7 to run queue
	CPU 3: Dispatched process  7
libfree:218
print_pgtbl:
 PDG=bdcc21000 P4g=bdd1ea000 PUD=bdcc16000 PMD=bdcc1a000
	CPU 2: Put process  5 to run queue
	CPU 2: Dispatched process  8
	CPU 0: Put process  3 to run queue
	CPU 0: Dispatched process  3
Time slot  14
liballoc:178
print_pgtbl:
 PDG=bdcc21000 P4g=bdd1ea000 PUD=bdcc16000 PMD=bdcc1a000
	CPU 1: Put process  4 to run queue
	CPU 1: Dispatched process  4
	CPU 0: Processed  3 has finished
	CPU 0: Dispatched process  5
Time slot  15
	CPU 3: Put process  7 to run queue
	CPU 3: Dispatched process  7
libfree:218
print_pgtbl:
 PDG=bdcc21000 P4g=bdd1ea000 PUD=bdcc16000 PMD=bdcc1a000
	CPU 2: Put process  8 to run queue
	CPU 2: Dispatched process  8
Time slot  16
libfree:218
print_pgtbl:
 PDG=bdcc21000 P4g=bdd1ea000 PUD=bdcc16000 PMD=bdcc1a000
	CPU 0: Put process  5 to run queue
	CPU 0: Dispatched process  5
	CPU 1: Put process  4 to run queue
	CPU 1: Dispatched process  4
Time slot  17
	CPU 3: Processed  7 has finished
	CPU 3: Dispatched process  6
	CPU 2: Put process  8 to run queue
	CPU 2: Dispatched process  8
Time slot  18
	CPU 1: Put process  4 to run queue
	CPU 1: Dispatched process  4
	CPU 0: Put process  5 to run queue
	CPU 0: Dispatched process  5
Time slot  19
	CPU 3: Put process  6 to run queue
	CPU 3: Dispatched process  6
	CPU 2: Put process  8 to run queue
	CPU 2: Dispatched process  8
Time slot  20
	CPU 1: Put process  4 to run queue
	CPU 1: Dispatched process  4
	CPU 0: Put process  5 to run queue
	CPU 0: Dispatched process  5
Time slot  21
	CPU 3: Put process  6 to run queue
	CPU 3: Dispatched process  6
	CPU 2: Put process  8 to run queue
	CPU 2: Dispatched process  8
Time slot  22
	CPU 1: Put process  4 to run queue
	CPU 1: Dispatched process  4
	CPU 0: Put process  5 to run queue
	CPU 0: Dispatched process  5
Time slot  23
	CPU 3: Put process  6 to run queue
	CPU 3: Dispatched process  6
	CPU 2: Put process  8 to run queue
	CPU 2: Dispatched process  8
Time slot  24
	CPU 0: Put process  5 to run queue
	CPU 0: Dispatched process  5
	CPU 1: Put process  4 to run queue
	CPU 1: Dispatched process  4
Time slot  25
	CPU 3: Put process  6 to run queue
	CPU 1: Processed  4 has finished
	CPU 1: Dispatched process  1
libread:426
	CPU 2: Put process  8 to run queue
	CPU 2: Dispatched process  8
	CPU 3: Dispatched process  6
print_pgtbl:
 PDG=bdcc03000 P4g=bdd1e4000 PUD=bdcc04000 PMD=bdcc08000
Time slot  26
	CPU 0: Processed  5 has finished
	CPU 0 stopped
Time slot  27
	CPU 3: Put process  6 to run queue
	CPU 3: Dispatched process  6
	CPU 1: Put process  1 to run queue
	CPU 1: Dispatched process  1
libfree:218
print_pgtbl:
 PDG=bdcc03000 P4g=bdd1e4000 PUD=bdcc04000 PMD=bdcc08000
	CPU 2: Put process  8 to run queue
	CPU 2: Dispatched process  8
Time slot  28
	CPU 2: Processed  8 has finished
	CPU 2 stopped
Time slot  29
	CPU 3: Processed  6 has finished
	CPU 3 stopped
	CPU 1: Processed  1 has finished
	CPU 1 stopped
