Time slot   0
ld_routine
Time slot   1
	Loaded a process at input/proc/p0s, PID: 1 PRIO: 130
	CPU 3: Dispatched process  1
Time slot   2
	Loaded a process at input/proc/m0s, PID: 2 PRIO: 120
	CPU 2: Dispatched process  2
liballoc:178
print_pgtbl:
 PDG=850c07000 P4g=85120e000 PUD=850c0c000 PMD=850c09000
liballoc:178
print_pgtbl:
 PDG=850c04000 P4g=85120d000 PUD=1011d2640 PMD=850c08000
Time slot   3
liballoc:178
print_pgtbl:
 PDG=850c07000 P4g=85120e000 PUD=850c0c000 PMD=850c09000
	CPU 3: Put process  1 to run queue
	CPU 3: Dispatched process  1
liballoc:178
print_pgtbl:
 PDG=850c04000 P4g=85120d000 PUD=1011d2640 PMD=850c08000
Time slot   4
	Loaded a process at input/proc/s3, PID: 3 PRIO: 39
	CPU 2: Put process  2 to run queue
	CPU 2: Dispatched process  2
libfree:218
print_pgtbl:
	CPU 1: Dispatched process  3
 PDG=850c04000 P4g=85120d000 PUD=1011d2640 PMD=850c08000
libfree:218
print_pgtbl:
 PDG=850c07000 P4g=85120e000 PUD=850c0c000 PMD=850c09000
Time slot   5
	Loaded a process at input/proc/s0, PID: 4 PRIO: 38
liballoc:178
	CPU 3: Put process  1 to run queue
	CPU 0: Dispatched process  4
	CPU 3: Dispatched process  1
liballoc:178
print_pgtbl:
 PDG=850c04000 P4g=85120d000 PUD=1011d2640 PMD=850c08000
print_pgtbl:
 PDG=850c07000 P4g=85120e000 PUD=850c0c000 PMD=850c09000
Time slot   6
	CPU 2: Put process  2 to run queue
libwrite:502
print_pgtbl:
 PDG=850c04000 P4g=85120d000 PUD=1011d2640 PMD=850c08000
	CPU 1: Put process  3 to run queue
	CPU 1: Dispatched process  3
	CPU 2: Dispatched process  2
libwrite:502
print_pgtbl:
 PDG=850c07000 P4g=85120e000 PUD=850c0c000 PMD=850c09000
Time slot   7
	CPU 3: Put process  1 to run queue
	CPU 3: Dispatched process  1
	CPU 0: Put process  4 to run queue
	CPU 0: Dispatched process  4
libread:426
print_pgtbl:
 PDG=850c04000 P4g=85120d000 PUD=1011d2640 PMD=850c08000
libwrite:502
print_pgtbl:
 PDG=850c07000 P4g=85120e000 PUD=850c0c000 PMD=850c09000
Time slot   8
libwrite:502
print_pgtbl:
 PDG=850c04000 P4g=85120d000 PUD=1011d2640 PMD=850c08000
	CPU 2: Processed  2 has finished
	CPU 1: Put process  3 to run queue
	CPU 1: Dispatched process  3
Time slot   9
	Loaded a process at input/proc/m1s, PID: 5 PRIO: 15
	CPU 2: Dispatched process  5
liballoc:178
	CPU 3: Put process  1 to run queue
	CPU 3: Dispatched process  1
libread:426
print_pgtbl:
 PDG=850c04000 P4g=85120d000 PUD=1011d2640 PMD=850c08000
	CPU 0: Put process  4 to run queue
	CPU 0: Dispatched process  4
print_pgtbl:
 PDG=850c18000 P4g=851211000 PUD=850c0f000 PMD=850c1c000
Time slot  10
	CPU 1: Put process  3 to run queue
	CPU 1: Dispatched process  3
libwrite:502
print_pgtbl:
 PDG=850c04000 P4g=85120d000 PUD=1011d2640 PMD=850c08000
liballoc:178
print_pgtbl:
 PDG=850c18000 P4g=851211000 PUD=850c0f000 PMD=850c1c000
Time slot  11
	Loaded a process at input/proc/p1s, PID: 6 PRIO: 15
	CPU 3: Put process  1 to run queue
	CPU 2: Put process  5 to run queue
	CPU 2: Dispatched process  5
libfree:218
	CPU 0: Put process  4 to run queue
	CPU 0: Dispatched process  4
	CPU 3: Dispatched process  6
print_pgtbl:
 PDG=850c18000 P4g=851211000 PUD=850c0f000 PMD=850c1c000
Time slot  12
liballoc:178
print_pgtbl:
 PDG=850c18000 P4g=851211000 PUD=850c0f000 PMD=850c1c000
	CPU 1: Put process  3 to run queue
	CPU 1: Dispatched process  3
Time slot  13
	Loaded a process at input/proc/s2, PID: 7 PRIO: 120
	CPU 3: Put process  6 to run queue
	CPU 3: Dispatched process  6
	CPU 0: Put process  4 to run queue
	CPU 0: Dispatched process  4
	CPU 2: Put process  5 to run queue
	CPU 2: Dispatched process  5
libfree:218
print_pgtbl:
 PDG=850c18000 P4g=851211000 PUD=850c0f000 PMD=850c1c000
Time slot  14
libfree:218
print_pgtbl:
 PDG=850c18000 P4g=851211000 PUD=850c0f000 PMD=850c1c000
	CPU 1: Put process  3 to run queue
	CPU 1: Dispatched process  3
Time slot  15
	CPU 3: Put process  6 to run queue
	CPU 3: Dispatched process  6
	CPU 0: Put process  4 to run queue
	CPU 0: Dispatched process  4
	CPU 2: Processed  5 has finished
	CPU 2: Dispatched process  7
Time slot  16
	Loaded a process at input/proc/s1, PID: 8 PRIO: 0
	CPU 1: Put process  3 to run queue
	CPU 1: Dispatched process  8
Time slot  17
	CPU 3: Put process  6 to run queue
	CPU 3: Dispatched process  6
	CPU 0: Put process  4 to run queue
	CPU 0: Dispatched process  4
	CPU 2: Put process  7 to run queue
	CPU 2: Dispatched process  3
Time slot  18
	CPU 1: Put process  8 to run queue
	CPU 1: Dispatched process  8
Time slot  19
	CPU 3: Put process  6 to run queue
	CPU 3: Dispatched process  6
	CPU 0: Put process  4 to run queue
	CPU 0: Dispatched process  4
	CPU 2: Put process  3 to run queue
	CPU 2: Dispatched process  3
Time slot  20
	CPU 1: Put process  8 to run queue
	CPU 1: Dispatched process  8
	CPU 0: Processed  4 has finished
	CPU 0: Dispatched process  7
Time slot  21
	CPU 3: Put process  6 to run queue
	CPU 3: Dispatched process  6
	CPU 2: Processed  3 has finished
	CPU 2: Dispatched process  1
libread:426
print_pgtbl:
 PDG=850c04000 P4g=85120d000 PUD=1011d2640 PMD=850c08000
Time slot  22
	CPU 1: Put process  8 to run queue
	CPU 1: Dispatched process  8
	CPU 0: Put process  7 to run queue
	CPU 0: Dispatched process  7
Time slot  23
	CPU 3: Put process  6 to run queue
	CPU 3: Dispatched process  6
	CPU 2: Put process  1 to run queue
	CPU 2: Dispatched process  1
libfree:218
print_pgtbl:
 PDG=850c04000 P4g=85120d000 PUD=1011d2640 PMD=850c08000
Time slot  24
	CPU 1: Put process  8 to run queue
	CPU 1: Dispatched process  8
	CPU 0: Put process  7 to run queue
	CPU 0: Dispatched process  7
Time slot  25
	CPU 3: Put process  6 to run queue
	CPU 3: Dispatched process  6
	CPU 2: Processed  1 has finished
	CPU 2 stopped
	CPU 1: Processed  8 has finished
	CPU 1 stopped
Time slot  26
	CPU 0: Put process  7 to run queue
	CPU 0: Dispatched process  7
Time slot  27
	CPU 3: Put process  6 to run queue
	CPU 3: Dispatched process  6
Time slot  28
	CPU 0: Put process  7 to run queue
	CPU 0: Dispatched process  7
Time slot  29
	CPU 3: Put process  6 to run queue
	CPU 3: Dispatched process  6
Time slot  30
	CPU 3: Processed  6 has finished
	CPU 3 stopped
	CPU 0: Processed  7 has finished
	CPU 0 stopped
