Time slot   0
ld_routine
Time slot   1
	Loaded a process at input/proc/p0s, PID: 1 PRIO: 130
	CPU 1: Dispatched process  1
Time slot   2
liballoc:178
print_pgtbl:
 PDG=c3920c000 P4g=c3920d000 PUD=c39210000 PMD=c39211000
Time slot   3
	Loaded a process at input/proc/m0s, PID: 2 PRIO: 120
	CPU 1: Put process  1 to run queue
	CPU 1: Dispatched process  2
liballoc:178
print_pgtbl:
 PDG=c3920e000 P4g=c3920f000 PUD=c39212000 PMD=c39213000
Time slot   4
	CPU 3: Dispatched process  1
liballoc:178
print_pgtbl:
 PDG=c3920c000 P4g=c3920d000 PUD=c39210000 PMD=c39211000
liballoc:178
print_pgtbl:
 PDG=c3920e000 P4g=c3920f000 PUD=c39212000 PMD=c39213000
Time slot   5
	Loaded a process at input/proc/s1, PID: 3 PRIO: 0
libfree:218
print_pgtbl:
 PDG=c3920c000 P4g=c3920d000 PUD=c39210000 PMD=c39211000
	CPU 1: Put process  2 to run queue
	CPU 1: Dispatched process  3
Time slot   6
	CPU 0: Dispatched process  2
libfree:218
print_pgtbl:
 PDG=c3920e000 P4g=c3920f000 PUD=c39212000 PMD=c39213000
	Loaded a process at input/proc/p1s, PID: 4 PRIO: 15
	CPU 3: Put process  1 to run queue
	CPU 3: Dispatched process  4
Time slot   7
	CPU 2: Dispatched process  1
liballoc:178
print_pgtbl:
 PDG=c3920c000 P4g=c3920d000 PUD=c39210000 PMD=c39211000
	CPU 1: Put process  3 to run queue
	CPU 1: Dispatched process  3
liballoc:178
print_pgtbl:
 PDG=c3920e000 P4g=c3920f000 PUD=c39212000 PMD=c39213000
Time slot   8
	CPU 3: Put process  4 to run queue
	CPU 3: Dispatched process  4
	CPU 0: Put process  2 to run queue
	CPU 0: Dispatched process  2
libwrite:502
print_pgtbl:
 PDG=c3920e000 P4g=c3920f000 PUD=c39212000 PMD=c39213000
libwrite:502
print_pgtbl:
 PDG=c3920c000 P4g=c3920d000 PUD=c39210000 PMD=c39211000
Time slot   9
	CPU 2: Put process  1 to run queue
	Loaded a process at input/proc/s3, PID: 5 PRIO: 39
	CPU 1: Put process  3 to run queue
	CPU 1: Dispatched process  3
	CPU 2: Dispatched process  1
libread:426
print_pgtbl:
 PDG=c3920c000 P4g=c3920d000 PUD=c39210000 PMD=c39211000
libwrite:502
print_pgtbl:
 PDG=c3920e000 P4g=c3920f000 PUD=c39212000 PMD=c39213000
Time slot  10
	CPU 3: Put process  4 to run queue
	CPU 3: Dispatched process  4
	CPU 0: Processed  2 has finished
libwrite:502
print_pgtbl:
 PDG=c3920c000 P4g=c3920d000 PUD=c39210000 PMD=c39211000
	CPU 0: Dispatched process  5
	Loaded a process at input/proc/s2, PID: 6 PRIO: 120
Time slot  11
	CPU 2: Put process  1 to run queue
	CPU 2: Dispatched process  6
	CPU 1: Put process  3 to run queue
	CPU 1: Dispatched process  3
	Loaded a process at input/proc/m1s, PID: 7 PRIO: 15
Time slot  12
	CPU 3: Put process  4 to run queue
	CPU 3: Dispatched process  7
liballoc:178
print_pgtbl:
 PDG=c39228000 P4g=c39229000 PUD=c3922c000 PMD=c3922d000
	Loaded a process at input/proc/s0, PID: 8 PRIO: 38
	CPU 0: Put process  5 to run queue
	CPU 0: Dispatched process  4
Time slot  13
liballoc:178
print_pgtbl:
	CPU 1: Put process  3 to run queue
	CPU 1: Dispatched process  3
	CPU 2: Put process  6 to run queue
	CPU 2: Dispatched process  8
 PDG=c39228000 P4g=c39229000 PUD=c3922c000 PMD=c3922d000
Time slot  14
	CPU 3: Put process  7 to run queue
	CPU 3: Dispatched process  7
	CPU 1: Processed  3 has finished
	CPU 1: Dispatched process  5
	CPU 0: Put process  4 to run queue
	CPU 0: Dispatched process  4
libfree:218
print_pgtbl:
 PDG=c39228000 P4g=c39229000 PUD=c3922c000 PMD=c3922d000
Time slot  15
liballoc:178
print_pgtbl:
 PDG=c39228000 P4g=c39229000 PUD=c3922c000 PMD=c3922d000
	CPU 2: Put process  8 to run queue
	CPU 2: Dispatched process  8
Time slot  16
	CPU 3: Put process  7 to run queue
	CPU 0: Put process  4 to run queue
	CPU 0: Dispatched process  4
	CPU 1: Put process  5 to run queue
	CPU 1: Dispatched process  5
	CPU 3: Dispatched process  7
libfree:218
print_pgtbl:
 PDG=c39228000 P4g=c39229000 PUD=c3922c000 PMD=c3922d000
Time slot  17
libfree:218
print_pgtbl:
 PDG=c39228000 P4g=c39229000 PUD=c3922c000 PMD=c3922d000
	CPU 2: Put process  8 to run queue
	CPU 2: Dispatched process  8
Time slot  18
	CPU 3: Processed  7 has finished
	CPU 0: Put process  4 to run queue
	CPU 0: Dispatched process  4
	CPU 3: Dispatched process  6
	CPU 1: Put process  5 to run queue
	CPU 1: Dispatched process  5
Time slot  19
	CPU 2: Put process  8 to run queue
	CPU 2: Dispatched process  8
Time slot  20
	CPU 3: Put process  6 to run queue
	CPU 0: Put process  4 to run queue
	CPU 0: Dispatched process  4
	CPU 1: Put process  5 to run queue
	CPU 1: Dispatched process  5
	CPU 3: Dispatched process  6
Time slot  21
	CPU 2: Put process  8 to run queue
	CPU 2: Dispatched process  8
Time slot  22
	CPU 3: Put process  6 to run queue
	CPU 3: Dispatched process  6
	CPU 0: Put process  4 to run queue
	CPU 0: Dispatched process  4
	CPU 1: Put process  5 to run queue
	CPU 1: Dispatched process  5
Time slot  23
	CPU 2: Put process  8 to run queue
	CPU 2: Dispatched process  8
Time slot  24
	CPU 3: Put process  6 to run queue
	CPU 3: Dispatched process  6
	CPU 0: Put process  4 to run queue
	CPU 0: Dispatched process  4
	CPU 1: Put process  5 to run queue
	CPU 1: Dispatched process  5
Time slot  25
	CPU 2: Put process  8 to run queue
	CPU 2: Dispatched process  8
	CPU 0: Processed  4 has finished
	CPU 0: Dispatched process  1
libread:426
print_pgtbl:
 PDG=c3920c000 P4g=c3920d000 PUD=c39210000 PMD=c39211000
Time slot  26
	CPU 3: Put process  6 to run queue
	CPU 1: Put process  5 to run queue
libwrite:502
print_pgtbl:
 PDG=c3920c000 P4g=c3920d000 PUD=c39210000 PMD=c39211000
	CPU 1: Dispatched process  5
	CPU 3: Dispatched process  6
Time slot  27
	CPU 2: Put process  8 to run queue
	CPU 2: Dispatched process  8
	CPU 0: Put process  1 to run queue
	CPU 0: Dispatched process  1
libread:426
print_pgtbl:
 PDG=c3920c000 P4g=c3920d000 PUD=c39210000 PMD=c39211000
Time slot  28
	CPU 3: Processed  6 has finished
	CPU 1: Processed  5 has finished
	CPU 1 stopped
	CPU 2: Processed  8 has finished
	CPU 2 stopped
	CPU 3 stopped
Time slot  29
	CPU 0: Put process  1 to run queue
	CPU 0: Dispatched process  1
libfree:218
print_pgtbl:
 PDG=c3920c000 P4g=c3920d000 PUD=c39210000 PMD=c39211000
Time slot  30
Time slot  31
	CPU 0: Processed  1 has finished
	CPU 0 stopped
