Time slot   0
ld_routine
Time slot   1
Time slot   2
Time slot   3
Time slot   4
Time slot   5
	Loaded a process at input/proc/m2s, PID: 1 PRIO: 120
Time slot   6
	CPU 3: Dispatched process  1
liballoc:178
print_pgtbl:
 PDG=8cf22c000 P4g=8cf22d000 PUD=8cec04000 PMD=8cec05000
Time slot   7
liballoc:178
print_pgtbl:
 PDG=8cf22c000 P4g=8cf22d000 PUD=8cec04000 PMD=8cec05000
Time slot   8
	CPU 3: Put process  1 to run queue
	CPU 3: Dispatched process  1
libfree:218
print_pgtbl:
 PDG=8cf22c000 P4g=8cf22d000 PUD=8cec04000 PMD=8cec05000
Time slot   9
	Loaded a process at input/proc/s0, PID: 2 PRIO: 38
Time slot  10
	CPU 3: Put process  1 to run queue
	CPU 3: Dispatched process  1
	CPU 2: Dispatched process  2
Time slot  11
	Loaded a process at input/proc/s3, PID: 3 PRIO: 39
	CPU 0: Dispatched process  3
Time slot  12
	CPU 3: Put process  1 to run queue
	CPU 2: Put process  2 to run queue
	CPU 2: Dispatched process  2
	CPU 3: Dispatched process  1
Time slot  13
	CPU 0: Put process  3 to run queue
	CPU 0: Dispatched process  3
Time slot  14
	CPU 3: Put process  1 to run queue
	CPU 3: Dispatched process  1
	CPU 2: Put process  2 to run queue
	CPU 2: Dispatched process  2
	Loaded a process at input/proc/m2s, PID: 4 PRIO: 15
Time slot  15
libfree:218
print_pgtbl:
 PDG=8cf22c000 P4g=8cf22d000 PUD=8cec04000 PMD=8cec05000
	CPU 1: Dispatched process  4
liballoc:178
print_pgtbl:
 PDG=8cf236000 P4g=8cf237000 PUD=8cec0a000 PMD=8cec0b000
	CPU 0: Put process  3 to run queue
	CPU 0: Dispatched process  3
Time slot  16
	CPU 3: Put process  1 to run queue
	CPU 3: Dispatched process  1
liballoc:178
	Loaded a process at input/proc/s2, PID: 5 PRIO: 120
libfree:218
print_pgtbl:
 PDG=8cf22c000 P4g=8cf22d000 PUD=8cec04000 PMD=8cec05000
print_pgtbl:
 PDG=8cf236000 P4g=8cf237000 PUD=8cec0a000 PMD=8cec0b000
	CPU 2: Put process  2 to run queue
	CPU 2: Dispatched process  2
Time slot  17
libfree:218
print_pgtbl:
 PDG=8cf22c000 P4g=8cf22d000 PUD=8cec04000 PMD=8cec05000
	CPU 1: Put process  4 to run queue
	Loaded a process at input/proc/s1, PID: 6 PRIO: 0
	CPU 1: Dispatched process  4
libfree:218
print_pgtbl:
 PDG=8cf236000 P4g=8cf237000 PUD=8cec0a000 PMD=8cec0b000
	CPU 0: Put process  3 to run queue
	CPU 0: Dispatched process  6
Time slot  18
	CPU 3: Processed  1 has finished
	CPU 2: Put process  2 to run queue
	CPU 2: Dispatched process  2
	CPU 3: Dispatched process  3
Time slot  19
	CPU 0: Put process  6 to run queue
	CPU 0: Dispatched process  6
	CPU 1: Put process  4 to run queue
	CPU 1: Dispatched process  4
Time slot  20
	CPU 3: Put process  3 to run queue
	CPU 3: Dispatched process  3
	CPU 2: Put process  2 to run queue
	CPU 2: Dispatched process  2
Time slot  21
	CPU 0: Put process  6 to run queue
	CPU 0: Dispatched process  6
	CPU 1: Put process  4 to run queue
	CPU 1: Dispatched process  4
Time slot  22
	CPU 3: Put process  3 to run queue
	CPU 3: Dispatched process  3
	CPU 2: Put process  2 to run queue
	CPU 2: Dispatched process  2
Time slot  23
	CPU 1: Put process  4 to run queue
	CPU 1: Dispatched process  4
	CPU 0: Put process  6 to run queue
	CPU 0: Dispatched process  6
Time slot  24
	CPU 3: Put process  3 to run queue
libfree:218
print_pgtbl:
 PDG=8cf236000 P4g=8cf237000 PUD=8cec0a000 PMD=8cec0b000
	CPU 3: Dispatched process  3
	CPU 2: Put process  2 to run queue
	CPU 2: Dispatched process  2
Time slot  25
	CPU 2: Processed  2 has finished
	CPU 2: Dispatched process  5
	CPU 0: Put process  6 to run queue
	CPU 0: Dispatched process  6
	CPU 1: Put process  4 to run queue
	CPU 1: Dispatched process  4
libfree:218
print_pgtbl:
 PDG=8cf236000 P4g=8cf237000 PUD=8cec0a000 PMD=8cec0b000
Time slot  26
	CPU 3: Put process  3 to run queue
	CPU 3: Dispatched process  3
libfree:218
print_pgtbl:
 PDG=8cf236000 P4g=8cf237000 PUD=8cec0a000 PMD=8cec0b000
	CPU 0: Processed  6 has finished
	CPU 0 stopped
Time slot  27
	CPU 2: Put process  5 to run queue
	CPU 2: Dispatched process  5
	CPU 1: Processed  4 has finished
	CPU 1 stopped
Time slot  28
	CPU 3: Processed  3 has finished
	CPU 3 stopped
Time slot  29
	CPU 2: Put process  5 to run queue
	CPU 2: Dispatched process  5
Time slot  30
Time slot  31
	CPU 2: Put process  5 to run queue
	CPU 2: Dispatched process  5
Time slot  32
Time slot  33
	CPU 2: Put process  5 to run queue
	CPU 2: Dispatched process  5
Time slot  34
Time slot  35
	CPU 2: Put process  5 to run queue
	CPU 2: Dispatched process  5
Time slot  36
Time slot  37
	CPU 2: Processed  5 has finished
	CPU 2 stopped
